<?xml version="1.0" encoding="UTF-8"?>
<testng-results ignored="0" total="2" passed="0" failed="1" skipped="1">
  <reporter-output>
  </reporter-output>
  <suite started-at="2023-09-01T17:29:21Z" name="Failed suite [Failed suite [Suite]]" finished-at="2023-09-01T17:29:44Z" duration-ms="23085">
    <groups>
      <group name="ErrorHandlingTest">
        <method signature="ErrorValidationsTest.LoginApplication()[pri:0, instance:testPrograms.ErrorValidationsTest@770d3326]" name="LoginApplication" class="testPrograms.ErrorValidationsTest"/>
      </group> <!-- ErrorHandlingTest -->
    </groups>
    <test started-at="2023-09-01T17:29:21Z" name="Test(failed)(failed)" finished-at="2023-09-01T17:29:44Z" duration-ms="23085">
      <class name="testPrograms.ErrorValidationsTest">
        <test-method is-config="true" signature="launchApplication()[pri:0, instance:testPrograms.ErrorValidationsTest@770d3326]" started-at="2023-09-01T17:29:21Z" name="launchApplication" finished-at="2023-09-01T17:29:36Z" duration-ms="15027" status="PASS">
          <reporter-output>
          </reporter-output>
        </test-method> <!-- launchApplication -->
        <test-method signature="LoginApplication()[pri:0, instance:testPrograms.ErrorValidationsTest@770d3326]" started-at="2023-09-01T17:29:36Z" name="LoginApplication" finished-at="2023-09-01T17:29:37Z" duration-ms="1027" status="SKIP">
          <exception class="java.lang.AssertionError">
            <message>
              <![CDATA[null]]>
            </message>
            <full-stacktrace>
              <![CDATA[java.lang.AssertionError: null
at org.testng.Assert.fail(Assert.java:96)
at org.testng.Assert.assertNotEquals(Assert.java:1157)
at org.testng.Assert.assertNotEquals(Assert.java:1162)
at testPrograms.ErrorValidationsTest.LoginApplication(ErrorValidationsTest.java:19)
at java.base/jdk.internal.reflect.NativeMethodAccessorImpl.invoke0(Native Method)
at java.base/jdk.internal.reflect.NativeMethodAccessorImpl.invoke(NativeMethodAccessorImpl.java:77)
at java.base/jdk.internal.reflect.DelegatingMethodAccessorImpl.invoke(DelegatingMethodAccessorImpl.java:43)
at java.base/java.lang.reflect.Method.invoke(Method.java:568)
at org.testng.internal.MethodInvocationHelper.invokeMethod(MethodInvocationHelper.java:124)
at org.testng.internal.Invoker.invokeMethod(Invoker.java:583)
at org.testng.internal.Invoker.invokeTestMethod(Invoker.java:719)
at org.testng.internal.Invoker.invokeTestMethods(Invoker.java:989)
at org.testng.internal.TestMethodWorker.invokeTestMethods(TestMethodWorker.java:125)
at org.testng.internal.TestMethodWorker.run(TestMethodWorker.java:109)
at org.testng.TestRunner.privateRun(TestRunner.java:648)
at org.testng.TestRunner.run(TestRunner.java:505)
at org.testng.SuiteRunner.runTest(SuiteRunner.java:455)
at org.testng.SuiteRunner.runSequentially(SuiteRunner.java:450)
at org.testng.SuiteRunner.privateRun(SuiteRunner.java:415)
at org.testng.SuiteRunner.run(SuiteRunner.java:364)
at org.testng.SuiteRunnerWorker.runSuite(SuiteRunnerWorker.java:52)
at org.testng.SuiteRunnerWorker.run(SuiteRunnerWorker.java:84)
at org.testng.TestNG.runSuitesSequentially(TestNG.java:1208)
at org.testng.TestNG.runSuitesLocally(TestNG.java:1137)
at org.testng.TestNG.runSuites(TestNG.java:1049)
at org.testng.TestNG.run(TestNG.java:1017)
at org.testng.remote.AbstractRemoteTestNG.run(AbstractRemoteTestNG.java:115)
at org.testng.remote.RemoteTestNG.initAndRun(RemoteTestNG.java:251)
at org.testng.remote.RemoteTestNG.main(RemoteTestNG.java:77)
]]>
            </full-stacktrace>
          </exception> <!-- java.lang.AssertionError -->
          <reporter-output>
          </reporter-output>
        </test-method> <!-- LoginApplication -->
        <test-method is-config="true" signature="tearDown()[pri:0, instance:testPrograms.ErrorValidationsTest@770d3326]" started-at="2023-09-01T17:29:37Z" name="tearDown" finished-at="2023-09-01T17:29:38Z" duration-ms="317" status="PASS">
          <reporter-output>
          </reporter-output>
        </test-method> <!-- tearDown -->
        <test-method is-config="true" signature="launchApplication()[pri:0, instance:testPrograms.ErrorValidationsTest@770d3326]" started-at="2023-09-01T17:29:38Z" name="launchApplication" finished-at="2023-09-01T17:29:43Z" duration-ms="5720" status="PASS">
          <reporter-output>
          </reporter-output>
        </test-method> <!-- launchApplication -->
        <test-method signature="LoginApplication()[pri:0, instance:testPrograms.ErrorValidationsTest@770d3326]" started-at="2023-09-01T17:29:43Z" name="LoginApplication" finished-at="2023-09-01T17:29:44Z" duration-ms="770" status="FAIL">
          <exception class="java.lang.AssertionError">
            <message>
              <![CDATA[null]]>
            </message>
            <full-stacktrace>
              <![CDATA[java.lang.AssertionError: null
at org.testng.Assert.fail(Assert.java:96)
at org.testng.Assert.assertNotEquals(Assert.java:1157)
at org.testng.Assert.assertNotEquals(Assert.java:1162)
at testPrograms.ErrorValidationsTest.LoginApplication(ErrorValidationsTest.java:19)
at java.base/jdk.internal.reflect.NativeMethodAccessorImpl.invoke0(Native Method)
at java.base/jdk.internal.reflect.NativeMethodAccessorImpl.invoke(NativeMethodAccessorImpl.java:77)
at java.base/jdk.internal.reflect.DelegatingMethodAccessorImpl.invoke(DelegatingMethodAccessorImpl.java:43)
at java.base/java.lang.reflect.Method.invoke(Method.java:568)
at org.testng.internal.MethodInvocationHelper.invokeMethod(MethodInvocationHelper.java:124)
at org.testng.internal.Invoker.invokeMethod(Invoker.java:583)
at org.testng.internal.Invoker.retryFailed(Invoker.java:839)
at org.testng.internal.Invoker.invokeTestMethods(Invoker.java:1010)
at org.testng.internal.TestMethodWorker.invokeTestMethods(TestMethodWorker.java:125)
at org.testng.internal.TestMethodWorker.run(TestMethodWorker.java:109)
at org.testng.TestRunner.privateRun(TestRunner.java:648)
at org.testng.TestRunner.run(TestRunner.java:505)
at org.testng.SuiteRunner.runTest(SuiteRunner.java:455)
at org.testng.SuiteRunner.runSequentially(SuiteRunner.java:450)
at org.testng.SuiteRunner.privateRun(SuiteRunner.java:415)
at org.testng.SuiteRunner.run(SuiteRunner.java:364)
at org.testng.SuiteRunnerWorker.runSuite(SuiteRunnerWorker.java:52)
at org.testng.SuiteRunnerWorker.run(SuiteRunnerWorker.java:84)
at org.testng.TestNG.runSuitesSequentially(TestNG.java:1208)
at org.testng.TestNG.runSuitesLocally(TestNG.java:1137)
at org.testng.TestNG.runSuites(TestNG.java:1049)
at org.testng.TestNG.run(TestNG.java:1017)
at org.testng.remote.AbstractRemoteTestNG.run(AbstractRemoteTestNG.java:115)
at org.testng.remote.RemoteTestNG.initAndRun(RemoteTestNG.java:251)
at org.testng.remote.RemoteTestNG.main(RemoteTestNG.java:77)
]]>
            </full-stacktrace>
          </exception> <!-- java.lang.AssertionError -->
          <reporter-output>
          </reporter-output>
        </test-method> <!-- LoginApplication -->
        <test-method is-config="true" signature="tearDown()[pri:0, instance:testPrograms.ErrorValidationsTest@770d3326]" started-at="2023-09-01T17:29:44Z" name="tearDown" finished-at="2023-09-01T17:29:44Z" duration-ms="179" status="PASS">
          <reporter-output>
          </reporter-output>
        </test-method> <!-- tearDown -->
      </class> <!-- testPrograms.ErrorValidationsTest -->
    </test> <!-- Test(failed)(failed) -->
  </suite> <!-- Failed suite [Failed suite [Suite]] -->
</testng-results>
